<?xml version="1.0" encoding="UTF-8"?>


<robot name="ezgripper" xmlns:xacro="http://www.ros.org/wiki/xacro">

  <!-- <xacro:include filename="$(find fcsc_description)/model/dulcinea/materials.urdf.xacro" /> -->


<!--macro name="ezgripper" params="*origin"-->

<macro name="ezgripper_dual" params="prefix parent_link *origin mimic parent_prefix">


    <!-- links -->

    <link name="${prefix}_ezgripper_palm_link">
      <visual>
        <origin xyz="0 0 0" rpy="0 0 0"/>
        <geometry>
          <mesh filename="package://ezgripper_driver/meshes/ezgripper_gen2/SAKE_Palm_Dual_Gen2.stl"/>
        </geometry>
        <material name="SkyBlue" />
      </visual>
      <collision>
        <origin xyz="0 0 0" rpy="0 0 0"/>
        <geometry>
          <mesh filename="package://ezgripper_driver/meshes/ezgripper_gen2/SAKE_Palm_Dual_Gen2.stl"/>
        </geometry>
      </collision>
    <inertial>
      <mass value=".3"/>
      <inertia ixx="0.01" ixy="0.0" ixz="0.0" iyy="0.01" iyz="0.0" izz="0.01"/>
    </inertial>
    </link>

    <joint name="${prefix}_ezgripper_connect" type="fixed">
        <xacro:insert_block name="origin" />
        <!-- <origin rpy="0 0 0" xyz="0.049 0.0 0.2"/> -->
        <parent link="${parent_link}"/>
        <child link="${prefix}_ezgripper_palm_link"/>
        <axis xyz="0 0 0"/>
        <!-- <limit effort="0" lower="-1.57075" upper="0.25" velocity="3.67"/> -->
    </joint>

    <ezgripper_finger_L1 prefix="${prefix}" postfix="1" reflect="1" />
    <ezgripper_finger_L1 prefix="${prefix}" postfix="2" reflect="1" />

    <ezgripper_finger_L2 prefix="${prefix}" postfix="1" reflect="1" />
    <ezgripper_finger_L2 prefix="${prefix}" postfix="2" reflect="1" />

    <xacro:unless value="${mimic}">
      <ezgripper_knuckle_palm_L1 prefix="${prefix}" postfix="1" reflectY="1" reflectZ="1" reflectR="1" mimic_test="false"/>
      <ezgripper_knuckle_palm_L1 prefix="${prefix}" postfix="2" reflectY="-1" reflectZ="1" reflectR="-1" mimic_test="true"/>

      <ezgripper_knuckle_L1_L2 prefix="${prefix}" postfix="1" reflectY="1" reflectZ="1" reflectR="-1" mimic_test="false"/>
      <ezgripper_knuckle_L1_L2 prefix="${prefix}" postfix="2" reflectY="-1" reflectZ="1" reflectR="1" mimic_test="true"/>

      <ezgripper_knuckle_trans prefix="${prefix}" postfix="1"/>
      <ezgripper_knuckle_L1_L2_trans prefix="${prefix}" postfix="1"/>
    </xacro:unless>
    <xacro:if value="${mimic}">
      <ezgripper_knuckle_palm_L1_mimic prefix="${prefix}" postfix="1" reflectY="1" reflectZ="1" reflectR="1" parent_prefix="${parent_prefix}"/>
      <ezgripper_knuckle_palm_L1_mimic prefix="${prefix}" postfix="2" reflectY="-1" reflectZ="1" reflectR="-1" parent_prefix="${parent_prefix}"/>

      <ezgripper_knuckle_L1_L2_mimic prefix="${prefix}" postfix="1" reflectY="1" reflectZ="1" reflectR="-1" parent_prefix="${parent_prefix}"/>
      <ezgripper_knuckle_L1_L2_mimic prefix="${prefix}" postfix="2" reflectY="-1" reflectZ="1" reflectR="1" parent_prefix="${parent_prefix}"/>
    </xacro:if>
</macro>


<macro name="ezgripper_finger_L1" params="prefix postfix reflect">
    <link name="${prefix}_ezgripper_finger_L1_${postfix}">
      <visual>
        <origin xyz="0 0 0" rpy="0 0 0"/>
        <geometry>
          <mesh filename="package://ezgripper_driver/meshes/ezgripper_gen2/SAKE_Finger_L1_Gen2.stl"/>
        </geometry>
        <material name="Gray" />
      </visual>
      <collision>
        <origin xyz="0 0 0" rpy="0 0 0"/>
        <geometry>
          <mesh filename="package://ezgripper_driver/meshes/ezgripper_gen2/SAKE_Finger_L1_Gen2.stl"/>
        </geometry>
      </collision>
      <inertial>
        <mass value=".025"/>
        <inertia ixx="0.01" ixy="0.0" ixz="0.0" iyy="0.01" iyz="0.0" izz="0.01"/>
      </inertial>
    </link>
</macro>


<macro name="ezgripper_finger_L2" params="prefix postfix reflect">
    <link name="${prefix}_ezgripper_finger_L2_${postfix}">
      <visual>
        <origin xyz="0 0 0" rpy="0 0 0"/>
        <geometry>
          <mesh filename="package://ezgripper_driver/meshes/ezgripper_gen2/SAKE_Finger_L2_Gen2.stl"/>
        </geometry>
        <material name="Gray" />
      </visual>
      <collision>
        <origin xyz="0 0 0" rpy="0 0 0"/>
        <geometry>
          <mesh filename="package://ezgripper_driver/meshes/ezgripper_gen2/SAKE_Finger_L2_Gen2.stl"/>
        </geometry>
      </collision>
      <inertial>
        <mass value=".025"/>
        <inertia ixx="0.01" ixy="0.0" ixz="0.0" iyy="0.01" iyz="0.0" izz="0.01"/>
      </inertial>
    </link>
</macro>




    <!-- joints -->


  <macro name="ezgripper_knuckle_palm_L1_mimic" params="prefix postfix reflectY reflectZ reflectR parent_prefix">
    <joint name="${prefix}_ezgripper_knuckle_palm_L1_${postfix}" type="continuous">
      <parent link="${prefix}_ezgripper_palm_link"/>
      <child link="${prefix}_ezgripper_finger_L1_${postfix}"/>
      <origin xyz="0.072569 ${reflectY*0.03} 0" rpy="${-1.5708 * reflectR} 0 ${1.57075 * reflectR}"/>
      <axis xyz="0 1 0"/>
      <limit lower="-3.14" upper="3.14" effort="1" velocity="3.67"/>
      <mimic joint="${parent_prefix}_ezgripper_knuckle_palm_L1_1"/>
    </joint>
    <gazebo>
      <plugin filename="libroboticsgroup_gazebo_mimic_joint_plugin.so" name="mimic_${prefix}_ezgripper_knuckle_palm_L1_${postfix}">
        <joint>${parent_prefix}_ezgripper_knuckle_palm_L1_1</joint>
        <mimicJoint>${prefix}_ezgripper_knuckle_palm_L1_${postfix}</mimicJoint>
        <multiplier>1.0</multiplier>
        <offset>0.0</offset>
      </plugin>
    </gazebo>
  </macro>

  <macro name="ezgripper_knuckle_L1_L2_mimic" params="prefix postfix reflectY reflectZ reflectR parent_prefix">
    <joint name="${prefix}_ezgripper_knuckle_L1_L2_${postfix}" type="continuous">
      <parent link="${prefix}_ezgripper_finger_L1_${postfix}"/>
      <child link="${prefix}_ezgripper_finger_L2_${postfix}"/>
      <origin xyz="0.052 0 0" rpy="0 0 0"/>
      <!-- origin xyz="0.06 0 0" rpy="${3.14159 * reflectR} 0 0"/-->
      <axis xyz="0 1 0"/>
      <limit lower="-3.14" upper="3.14" effort="1" velocity="3.67"/>
      <mimic joint="${parent_prefix}_ezgripper_knuckle_L1_L2_1"/>
    </joint>
    <gazebo>
      <plugin filename="libroboticsgroup_gazebo_mimic_joint_plugin.so" name="mimic_${prefix}_ezgripper_knuckle_L1_L2_${postfix}">
        <mimicJoint>${prefix}_ezgripper_knuckle_L1_L2_${postfix}</mimicJoint>
          <joint>${parent_prefix}_ezgripper_knuckle_L1_L2_1</joint>
          <multiplier>1.0</multiplier>
          <offset>0.0</offset>
      </plugin>
    </gazebo>
  </macro>

  <macro name="ezgripper_knuckle_palm_L1" params="prefix postfix reflectY reflectZ reflectR mimic_test">
    <xacro:if value="${mimic_test}">
      <joint name="${prefix}_ezgripper_knuckle_palm_L1_${postfix}" type="continuous">
        <parent link="${prefix}_ezgripper_palm_link"/>
        <child link="${prefix}_ezgripper_finger_L1_${postfix}"/>
        <origin xyz="0.072569 ${reflectY*0.03} 0" rpy="${-1.5708 * reflectR} 0 ${1.57075 * reflectR}"/>
        <axis xyz="0 1 0"/>
        <limit lower="-3.14" upper="3.14" effort="1" velocity="3.67"/>
        <mimic joint="${prefix}_ezgripper_knuckle_palm_L1_1"/>
      </joint>
      <gazebo>
        <plugin filename="libroboticsgroup_gazebo_mimic_joint_plugin.so" name="mimic_${prefix}_ezgripper_knuckle_palm_L1_${postfix}">
          <joint>${prefix}_ezgripper_knuckle_palm_L1_1</joint>
          <mimicJoint>${prefix}_ezgripper_knuckle_palm_L1_${postfix}</mimicJoint>
          <multiplier>1.0</multiplier>
          <offset>0.0</offset>
        </plugin>
      </gazebo>
    </xacro:if>
    <xacro:unless value="${mimic_test}">
      <joint name="${prefix}_ezgripper_knuckle_palm_L1_${postfix}" type="revolute">
        <parent link="${prefix}_ezgripper_palm_link"/>
        <child link="${prefix}_ezgripper_finger_L1_${postfix}"/>
        <origin xyz="0.072569 ${reflectY*0.03} 0" rpy="${-1.5708 * reflectR} 0 ${1.57075 * reflectR}"/>
        <axis xyz="0 1 0"/>
        <limit lower="0" upper="1.94" effort="1" velocity="3.67"/>
      </joint>
    </xacro:unless>
  </macro>

  <macro name="ezgripper_knuckle_L1_L2" params="prefix postfix reflectY reflectZ reflectR mimic_test">
    <xacro:unless value="${mimic_test}">
      <joint name="${prefix}_ezgripper_knuckle_L1_L2_${postfix}" type="revolute">
        <parent link="${prefix}_ezgripper_finger_L1_${postfix}"/>
        <child link="${prefix}_ezgripper_finger_L2_${postfix}"/>
        <origin xyz="0.052 0 0" rpy="0 0 0"/>
        <!-- origin xyz="0.06 0 0" rpy="${3.14159 * reflectR} 0 0"/-->
        <axis xyz="0 1 0"/>
        <limit lower="0" upper="1.94" effort="1" velocity="3.67"/>
      </joint>
    </xacro:unless>
    <xacro:if value="${mimic_test}">
      <joint name="${prefix}_ezgripper_knuckle_L1_L2_${postfix}" type="continuous">
        <parent link="${prefix}_ezgripper_finger_L1_${postfix}"/>
        <child link="${prefix}_ezgripper_finger_L2_${postfix}"/>
        <origin xyz="0.052 0 0" rpy="0 0 0"/>
        <!-- origin xyz="0.06 0 0" rpy="${3.14159 * reflectR} 0 0"/-->
        <axis xyz="0 1 0"/>
        <limit lower="-3.14" upper="3.14" effort="1" velocity="3.67"/>
        <mimic joint="${prefix}_ezgripper_knuckle_L1_L2_1"/>
      </joint>
      <gazebo>
        <plugin filename="libroboticsgroup_gazebo_mimic_joint_plugin.so" name="mimic_${prefix}_ezgripper_knuckle_L1_L2_${postfix}">
            <joint>${prefix}_ezgripper_knuckle_L1_L2_1</joint>
            <mimicJoint>${prefix}_ezgripper_knuckle_L1_L2_${postfix}</mimicJoint>
            <multiplier>1.0</multiplier>
            <offset>0.0</offset>
        </plugin>
      </gazebo>
    </xacro:if>
  </macro>
  <!-- transmissions for Gazebo -->

  <macro name="ezgripper_knuckle_trans" params="prefix postfix">
    <transmission name="${prefix}_ezgripper_trans_${postfix}">
      <type>transmission_interface/SimpleTransmission</type>
      <joint name="${prefix}_ezgripper_knuckle_palm_L1_${postfix}">
        <hardwareInterface>hardware_interface/PositionJointInterface</hardwareInterface>
      </joint>
      <actuator name="${prefix}_ezgripper_motor${postfix}">
        <mechanicalReduction>1</mechanicalReduction>
        <hardwareInterface>hardware_interface/PositionJointInterface</hardwareInterface>
      </actuator>
    </transmission>
  </macro>
  <macro name="ezgripper_knuckle_L1_L2_trans" params="prefix postfix">
    <transmission name="${prefix}_ezgripper_knuckle_L1_L2_trans_${postfix}">
      <type>transmission_interface/SimpleTransmission</type>
      <joint name="${prefix}_ezgripper_knuckle_L1_L2_${postfix}">
        <hardwareInterface>hardware_interface/PositionJointInterface</hardwareInterface>
      </joint>
      <actuator name="${prefix}_ezgripper_knuckle_L1_L2_motor${postfix}">
        <mechanicalReduction>1</mechanicalReduction>
        <hardwareInterface>hardware_interface/PositionJointInterface</hardwareInterface>
      </actuator>
    </transmission>
  </macro>

  <!-- <link name="world"/> -->

  <!-- <ezgripper_dual prefix="top" parent_link="world" mimic="false" parent_prefix="top">
    <origin xyz="${0.01 + 0.0297} 0 ${0.065/2}" rpy="0 0 0"/>
  </ezgripper_dual>
  <ezgripper_dual prefix="bottom" parent_link="world"  mimic="true" parent_prefix="top">
    <origin xyz="${0.01+ 0.0297} 0 ${-0.065/2}" rpy="0 0 0"/>
  </ezgripper_dual> -->

</robot>
