<?xml version="1.0" encoding="UTF-8"?>
<robot name="ezgripper" xmlns:xacro="http://www.ros.org/wiki/xacro">

<xacro:macro name="ezgripper_quad" params="prefix parent_link *origin">

    <!-- links -->

    <link name="${prefix}_ezgripper_palm_link">
      <visual>
        <origin xyz="0 0 0" rpy="0 0 0"/>
        <geometry>
          <mesh filename="package://ezgripper_driver/meshes/visual/SAKE_Palm_Quad.stl"/>
        </geometry>
      </visual>
      <collision>
        <origin xyz="0 0 0" rpy="0 0 0"/>
        <geometry>
          <mesh filename="package://ezgripper_driver/meshes/collision/SAKE_Palm_Quad.stl"/>
        </geometry>
      </collision>
    <inertial>
      <mass value="0.3"/>
      <inertia ixx="0.01" ixy="0.0" ixz="0.0" iyy="0.01" iyz="0.0" izz="0.01"/>
    </inertial>
    </link>

    <!-- original -->
    <!-- <joint name="${prefix}_ezgripper_connect" type="fixed">
        <origin rpy="-1.57 0 0" xyz="0.049 0.0 0.2"/>
        <parent link="${parent_link}"/>
        <child link="${prefix}_ezgripper_palm_link"/>
        <axis xyz="0 0 0"/>
        <limit effort="0" lower="-1.57075" upper="0.25" velocity="3.67"/>
    </joint> -->

    <joint name="${prefix}_ezgripper_connect" type="fixed">
        <!-- <origin rpy="0 0 0" xyz="0 0 0"/> -->
        <xacro:insert_block name="origin"/>
        <parent link="${parent_link}"/>
        <child link="${prefix}_ezgripper_palm_link"/>
        <axis xyz="0 0 0"/>
        <limit effort="0" lower="-1.57075" upper="0.25" velocity="3.67"/>
    </joint>

    <ezgripper_lower_finger prefix="${prefix}" postfix="1"/>
    <ezgripper_lower_finger prefix="${prefix}" postfix="2"/>
    <ezgripper_lower_finger prefix="${prefix}" postfix="3"/>
    <ezgripper_lower_finger prefix="${prefix}" postfix="4"/>

    <ezgripper_knuckle prefix="${prefix}" postfix="1" reflectY="1" reflectZ="1" reflectR="1" mimic_test="false"/>
    <ezgripper_knuckle prefix="${prefix}" postfix="2" reflectY="-1" reflectZ="1" reflectR="-1" mimic_test="true"/>
    <ezgripper_knuckle prefix="${prefix}" postfix="3" reflectY="1" reflectZ="-1" reflectR="1" mimic_test="true"/>
    <ezgripper_knuckle prefix="${prefix}" postfix="4" reflectY="-1" reflectZ="-1" reflectR="-1" mimic_test="true"/>

    <ezgripper_knuckle_trans prefix="${prefix}" postfix="1"/>
    <!-- <ezgripper_knuckle_trans prefix="${prefix}" postfix="2"/>
    <ezgripper_knuckle_trans prefix="${prefix}" postfix="3"/>
    <ezgripper_knuckle_trans prefix="${prefix}" postfix="4"/> -->


    <ezgripper_upper_finger prefix="${prefix}" postfix="1"/>
    <ezgripper_upper_finger prefix="${prefix}" postfix="2"/>
    <ezgripper_upper_finger prefix="${prefix}" postfix="3"/>
    <ezgripper_upper_finger prefix="${prefix}" postfix="4"/>


    <ezgripper_finger prefix="${prefix}" postfix="1" reflectY="1" reflectZ="1" reflectR="1" mimic_test="false"/>
    <ezgripper_finger prefix="${prefix}" postfix="2" reflectY="-1" reflectZ="1" reflectR="-1" mimic_test="true"/>
    <ezgripper_finger prefix="${prefix}" postfix="3" reflectY="1" reflectZ="-1" reflectR="1" mimic_test="true"/>
    <ezgripper_finger prefix="${prefix}" postfix="4" reflectY="-1" reflectZ="-1" reflectR="-1" mimic_test="true"/>

    <ezgripper_finger_trans prefix="${prefix}" postfix="1"/>
    <!-- <ezgripper_finger_trans prefix="${prefix}" postfix="2"/>
    <ezgripper_finger_trans prefix="${prefix}" postfix="3"/>
    <ezgripper_finger_trans prefix="${prefix}" postfix="4"/> -->

    <ezgripper_gazebo_mimic prefix="${prefix}" postfix="1" reflect="1" mimic_test="false" />
    <ezgripper_gazebo_mimic prefix="${prefix}" postfix="2" reflect="1.0" mimic_test="true" />
    <ezgripper_gazebo_mimic prefix="${prefix}" postfix="3" reflect="1.0" mimic_test="true" />
    <ezgripper_gazebo_mimic prefix="${prefix}" postfix="4" reflect="1.0" mimic_test="true" />

</xacro:macro>

<macro name="ezgripper_gazebo_mimic" params="prefix postfix reflect mimic_test">
  <xacro:if value="${mimic_test}">
    <gazebo>
      <plugin filename="libroboticsgroup_gazebo_mimic_joint_plugin.so" name="mimic_${prefix}_ezgripper_knuckle_${postfix}">
          <joint>${prefix}_ezgripper_knuckle_1</joint>
          <mimicJoint>${prefix}_ezgripper_knuckle_${postfix}</mimicJoint>
          <multiplier>1.0</multiplier>
          <offset>0.0</offset>
      </plugin>
      <plugin filename="libroboticsgroup_gazebo_mimic_joint_plugin.so" name="mimic_${prefix}_ezgripper_finger_${postfix}">
          <joint>${prefix}_ezgripper_finger_1</joint>
          <mimicJoint>${prefix}_ezgripper_finger_${postfix}</mimicJoint>
          <multiplier>1.0</multiplier>
          <offset>0.0</offset>
      </plugin>
    </gazebo>
  </xacro:if>
</macro>

<macro name="ezgripper_lower_finger" params="prefix postfix">
    <link name="${prefix}_ezgripper_lower_finger_${postfix}">
      <visual>
        <origin xyz="0 0 0" rpy="0 0 0"/>
        <geometry>
          <mesh filename="package://ezgripper_driver/meshes/visual/SAKE_Finger_lower.stl"/>
        </geometry>
      </visual>
      <collision>
        <origin xyz="0 0 0" rpy="0 0 0"/>
        <geometry>
          <mesh filename="package://ezgripper_driver/meshes/collision/SAKE_Finger_lower.stl"/>
        </geometry>
      </collision>
      <inertial>
        <mass value="${0.025/2.0}"/>
        <inertia ixx="0.01" ixy="0.0" ixz="0.0" iyy="0.01" iyz="0.0" izz="0.01"/>
      </inertial>
    </link>
    <gazebo reference="${prefix}_ezgripper_lower_finger_${postfix}">
      <mu1 value="100000000000000000000" />
      <mu2 value="100000000000000000000" />
      <maxContacts>100</maxContacts>
    </gazebo>
</macro>

<macro name="ezgripper_upper_finger" params="prefix postfix">
    <link name="${prefix}_ezgripper_upper_finger_${postfix}">
      <visual>
        <origin xyz="${0.065} 0 0" rpy="0 0 0"/>
        <geometry>
          <mesh filename="package://ezgripper_driver/meshes/visual/SAKE_Finger_upper.stl"/>
        </geometry>
      </visual>
      <collision>
        <origin xyz="${0.065} 0 0" rpy="0 0 0"/>
        <geometry>
          <mesh filename="package://ezgripper_driver/meshes/collision/SAKE_Finger_upper.stl"/>
        </geometry>
      </collision>
      <inertial>
        <origin xyz="${0.065} 0 0" rpy="0 0 0"/>
        <mass value="${0.025/2.0}"/>
        <inertia ixx="0.01" ixy="0.0" ixz="0.0" iyy="0.01" iyz="0.0" izz="0.01"/>
      </inertial>
    </link>
    <gazebo reference="${prefix}_ezgripper_upper_finger_${postfix}">
      <mu1 value="100000000000000000000" />
      <mu2 value="100000000000000000000" />
      <maxContacts>100</maxContacts>
    </gazebo>
</macro>


    <!-- joints -->



<macro name="ezgripper_knuckle" params="prefix postfix reflectY reflectZ reflectR mimic_test">
  <xacro:if value="${mimic_test}">
    <joint name="${prefix}_ezgripper_knuckle_${postfix}" type="continuous">
      <parent link="${prefix}_ezgripper_palm_link"/>
      <child link="${prefix}_ezgripper_lower_finger_${postfix}"/>
      <origin xyz="0.1056 ${reflectY*0.03} ${reflectZ*0.03}" rpy="${1.5708 * reflectR} 0 3.14159"/>
      <axis xyz="0 1 0"/>
      <limit lower="-3.14" upper="3.14" effort="1" velocity="3.67"/>
      <mimic joint="${prefix}_ezgripper_knuckle_1" multiplier="1" offset="0"/>
      <dynamics damping="0.7"/>
    </joint>
  </xacro:if>
  <xacro:unless value="${mimic_test}">
    <joint name="${prefix}_ezgripper_knuckle_${postfix}" type="revolute">
      <parent link="${prefix}_ezgripper_palm_link"/>
      <child link="${prefix}_ezgripper_lower_finger_${postfix}"/>
      <origin xyz="0.1056 ${reflectY*0.03} ${reflectZ*0.03}" rpy="${1.5708 * reflectR} 0 3.14159"/>
      <axis xyz="0 1 0"/>
      <limit lower="-0.27" upper="1.57075" effort="1" velocity="3.67"/>
      <dynamics damping="0.7"/>
    </joint>
  </xacro:unless>
  <gazebo reference="${prefix}_ezgripper_knuckle_${postfix}">
    <implicitSprignDamper>1</implicitSprignDamper>
  </gazebo>
</macro>

<macro name="ezgripper_finger" params="prefix postfix reflectY reflectZ reflectR mimic_test">
  <xacro:if value="${mimic_test}">
    <joint name="${prefix}_ezgripper_finger_${postfix}" type="continuous">
      <parent link="${prefix}_ezgripper_lower_finger_${postfix}"/>
      <child link="${prefix}_ezgripper_upper_finger_${postfix}"/>
      <origin xyz="-0.0645 0 0" rpy="0 0 0"/>
      <axis xyz="0 1 0"/>
      <limit lower="-3.14" upper="3.14" effort="1" velocity="3.67"/>
      <mimic joint="${prefix}_ezgripper_finger_1" multiplier="1" offset="0"/>
      <dynamics damping="0.7"/>
    </joint>
  </xacro:if >
  <xacro:unless value="${mimic_test}">
    <joint name="${prefix}_ezgripper_finger_${postfix}" type="revolute">
      <parent link="${prefix}_ezgripper_lower_finger_${postfix}"/>
      <child link="${prefix}_ezgripper_upper_finger_${postfix}"/>
      <origin xyz="-0.0645 0 0" rpy="0 0 0"/>
      <axis xyz="0 1 0"/>
      <limit lower="-1.5707" upper="0" effort="1" velocity="3.67"/>
      <dynamics damping="0.7"/>
    </joint>
  </xacro:unless>
  <gazebo reference="${prefix}_ezgripper_finger_${postfix}">
    <implicitSpringDamper>1</implicitSpringDamper>
  </gazebo>
</macro>

    <!-- transmissions for Gazebo -->

<macro name="ezgripper_knuckle_trans" params="prefix postfix">
   <transmission name="${prefix}_ezgripper_trans_${postfix}">
      <type>transmission_interface/SimpleTransmission</type>
      <joint name="${prefix}_ezgripper_knuckle_${postfix}">
         <hardwareInterface>PositionJointInterface</hardwareInterface>
      </joint>
      <actuator name="${prefix}_ezgripper_motor${postfix}">
         <mechanicalReduction>1</mechanicalReduction>
         <hardwareInterface>PositionJointInterface</hardwareInterface>
      </actuator>
   </transmission>
</macro>

<macro name="ezgripper_finger_trans" params="prefix postfix">
   <transmission name="${prefix}_ezgripper_finger_trans_${postfix}">
      <type>transmission_interface/SimpleTransmission</type>
      <joint name="${prefix}_ezgripper_finger_${postfix}">
         <hardwareInterface>PositionJointInterface</hardwareInterface>
      </joint>
      <actuator name="${prefix}_ezgripper_finger_motor${postfix}">
         <mechanicalReduction>1</mechanicalReduction>
         <hardwareInterface>PositionJointInterface</hardwareInterface>
      </actuator>
   </transmission>
</macro>
</robot>
